Workbook

Sheet Read Me
A1: Women's Flat Track Derby Association
A2: IGRF & Standardized Stats Calculator
A3: April 2024 Release
A4: For use with January 1, 2023 The Rules of Flat Track Roller Derby
A6: Published by the Women's Flat Track Derby Association (WFTDA) 5900 Balcones Drive STE 4125, Austin, TX 78731, USA
A8: Modifications beyond those necessary for formatted printing are only allowed with the consent of the Women's Flat Track Derby Association. The Interleague Game Reporting Form and Standardized Stats Calculator ("StatsBook") and its contents may not be reproduced, distributed, or translated in whole or in part in any manner without the permission of the WFTDA.
A10: For Sanctioned games only:
A11: The host team follows the timeline and process for submitting required sanctioning data described in the WFTDA Sanctioning policy. The current WFTDA Sanctioning policy may be found at:
A12: https://resources.wftda.org/competition/wftda-competition-and-rankings/
A14: Instructions
A16: Detailed instructions for using the StatsBook are available in the StatsBook Manual, available at
A17: https://resources.wftda.org/competition/statsbook/
... A20: Please name your StatsBook file: STATS-YYYY-MM-DD_HostLeague_TeamName_vs_VisitorLeague_TeamName.
B21: Example: "STATS-2018-02-16_ToasterCityRollerDerby_Allstars_vs_WaterCity_AllStars.xlsx"
A22: Please name your scanned IGRF: IGRF-YYYY-MM-DD_HostLeague_TeamName_vs_VisitorLeague_TeamName.
B23: Example: "IGRF-2018-02-16_ToasterCityRollerDerby_Allstars_vs_WaterCity_AllStars.pdf"
A25: StatsBook/IGRF Instructions
B26: Submitting IGRFs
B27: Within 48 hours of game or tournament completion, the responsible party/host league representative should submit the following (scans or clear photos) to igrf@wftda.com
B28: 1. Both pages of the IGRF form, signed by both captains and head officials
B29: 2. Any Official Reviews should be tracked on the Official Review Form. If there are none, indicate this on the IGRF and you do not need to send in blank forms. If there are any, please indicate this on the IGRF and scan and submit the Official Review forms with the IGRF.
B30: 3. Expulsion-Suspension Forms: If there are no expulsions, indicate this on the IGRF and you do not need to send in blank forms. If there was an expulsion or expulsions, all parties should sign the form and provide email addresses in case WFTDA needs to follow up on the incident. Comments are not required and signatures do not indicate agreement with what other parties have written. See the WFTDA Expulsion and Suspension Policy for more information: https://resources.wftda.org/competition/wftda-competition-and-rankings/
B32: Submitting Statsbooks
B33: Please upload your completed StatsBooks to https://forms.gle/CMTPQYs6XhFHPkBE6 within two(2) weeks of the game or event. See Statsbook Manual for further instructions
A35: PLEASE NOTE: The host league is responsible for turning in the completed StatsBook and signed IGRF to WFTDA Sanctioning; however, Sanctioning will accept documents from either team. Captains from both teams should also receive a copy of the completed StatsBook and signed IGRF.
A36: Please do not abbreviate your league or team when naming documents for sanctioning.
A37: The StatsBook is provided by the WFTDA and contributors "as is" and any express or implied warranties, including, but not limited to, the implied warranties or merchantability and fitness for a particular purpose are disclaimed. In no event shall the WFTDA be liable for any direct, indirect, incidental, special, exemplary, or consequential damages (including, but not limited to, procurement of substitute goods or services; loss of use, data, or profits; or business interruption) however caused and on any theory of liability, whether in contract, strict liability, or tort (including negligence or otherwise) arising in any way out of the use of the StatsBook, even if advised of the possibility of such damage.

Sheet IGRF
A1: WFTDA Interleague Game Reporting Form (IGRF)
A2: Section 1. VENUE & ROSTERS (Complete BEFORE the game)
A3: Location: | B3: Boulder County Fairgrounds Exhibit Bldg. | I3: Longmont | K3: CO | L3: 1
B4: VENUE NAME | I4: CITY | K4: ST/PRV | L4: GAME #
A5: Tournament/ Multi-Day Event: | I5: Boulder County Roller Derby
B6: TOURNAMENT/MULTI-DAY EVENT NAME | I6: HOST LEAGUE NAME
A7: Date: | B7: 46123 | G7: Start Time: | I7: 0.59027778 | K7: Suspension: | L7: NO
A8: TEAM ROSTERS - List in order of Skater number
A9: H O M E T E A M | G9: V I S I T I N G T E A M
A10: LEAGUE | B10: BOULDER COUNTY ROLLER DERBY | G10: LEAGUE | I10: ROCKY MOUNTAIN ROLLER DERBY
A11: TEAM | B11: FLATIRON PHOENIXES | G11: TEAM | I11: 5280 FIGHT CLUB
A12: COLOR | B12: WHITE | G12: COLOR | I12: BLACK
A13: # of players | B13: Skater # | C13: Skater Name | G13: # of players | I13: Skater # | J13: Skater Name
A14: 1 | B14: 113 | C14: Short Stack | G14: 1 | I14: 008 | J14: HAM Wheezy | M14: HOH
A15: 2 | B15: 114 | C15: Cat Claus | F15: C | G15: 2 | I15: 1 | J15: Pink FlameNgo
A16: 3 | B16: 1190 | C16: Rickashanaynay | G16: 3 | I16: 11 | J16: Oy Vey Maria
A17: 4 | B17: 213 | C17: Primeval | G17: 4 | I17: 3 | J17: Zoom Bayou
A18: 5 | B18: 22 | C18: Penelope Bruise | G18: 5 | I18: 303 | J18: Reck 'em Ralph
A19: 6 | B19: 33 | C19: Ivy Profen | G19: 6 | I19: 4 | J19: Sweet Cyanide
A20: 7 | B20: 333 | C20: Honey Badger | F20: HOH | G20: 7 | I20: 406 | J20: Ruth Slayed-Her Ginsburg
A21: 8 | B21: 393 | C21: Miss EDventure | F21: ALT | G21: 8 | I21: 555 | J21: Mortal Wombat | M21: C
A22: 9 | B22: 504 | C22: Fleur de Beast | G22: 9 | I22: 71 | J22: TchaiKILLsky | M22: HOH
A23: 10 | B23: 69 | C23: Jungla | G23: 10 | I23: 716 | J23: Slim S’Kaity
A24: 11 | B24: 7 | C24: Freddie Mercury Poisoning | G24: 11 | I24: 76 | J24: Fiona Grapple | M24: HOH
A25: 12 | B25: 720 | C25: Bob Gnarly | G25: 12 | I25: 91 | J25: Poh Teigh Toh
A26: 13 | B26: 737 | C26: Lady J | F26: HOH | G26: 13 | I26: 96 | J26: Audubondage
A27: 14 | B27: 802 | C27: Rutabaga Ginsberg (Baga) | G27: 14 | I27: 9707 | J27: BATass
A28: 15 | B28: 86 | C28: Glidezilla | G28: 15 | I28: 99 | J28: May Q. Pay
A29: 16 | B29: 98 | C29: Badelynn | G29: 16
A30: 17 | G30: 17
A31: 18 | G31: 18
A32: 19 | G32: 19
A33: 20 | G33: 20
A34: Section 2. SCORE & PENALTIES (Complete DURING or IMMEDIATELY AFTER game)
A35: HOME TEAM | H35: VISITING TEAM
A36: Period 1 | B36: Points | C36: =IF(COUNT(Score!A4:A41)=0,"",Score!R42) -> 68 | D36: Penalties | F36: =IF(COUNT(Score!A4:A41)=0,"",Penalties!L44) -> 14 | H36: Period 1 | I36: Points | J36: =IF(COUNT(Score!T4:T41)=0,"",Score!AK42) -> 120 | K36: Penalties | L36: =IF(COUNT(Score!T4:T41)=0,"",Penalties!AA44) -> 9
A37: Period 2 | B37: Points | C37: =IF(COUNT(Score!A46:A83)=0,"",Score!R84-C36) -> 69 | D37: Penalties | F37: =IF(COUNT(Score!A46:A83)=0,"",Penalties!AN44) -> 15 | H37: Period 2 | I37: Points | J37: =IF(COUNT(Score!T46:T83)=0,"",Score!AK84-J36) -> 150 | K37: Penalties | L37: =IF(COUNT(Score!T46:T83)=0,"",Penalties!BC44) -> 14
A38: TOTAL POINTS: | C38: =IF(COUNT(Score!A4:A41)=0,"",SUM(C36:C37)) -> 137 | D38: PENALTIES: | F38: =IF(COUNT(Score!A4:A41)=0,"",SUM(F36:F37)) -> 29 | H38: TOTAL POINTS: | J38: =IF(COUNT(Score!T4:T41)=0,"",SUM(J36:J37)) -> 270 | K38: PENALTIES: | L38: =IF(COUNT(Score!T4:T41)=0,"",SUM(L36:L37)) -> 23
A39: The Official Score in this game required adjustment: | D39: NO | F39: Reason for OS adjustment:
A40: Expulsion/Suspension notes: | C40: Suspension was served by:
...

Sheet Game Summary
A1: W F T D A R E Q U I R E D S T A N D A R D I Z E D S T A T S
A2: =IF(IGRF!B10="","PLEASE FILL IN THE IGRF TAB!",IGRF!$B$10&" / "&IGRF!$B$11&" vs. "&IGRF!$I$10&" / "&IGRF!$I$11&IF(IGRF!$L$3="",""," Game "&IGRF!$L$3)) -> BOULDER COUNTY ROLLER DERBY / FLATIRON PHOENIXES vs. ROCKY MOUNTAIN ROLLER DERBY / 5280 FIGHT CLUB Game 1
A3: =IF(IGRF!$B$7="","ENTER DATE ON IGRF TAB!",IGRF!$B$7) -> 46123
A4: ROSTERS | C4: JAMS PLAYED | J4: LEAD JAMMER | R4: POINTS FOR/AGAINST & PLUS/MINUS | AD4: V.T.A.R. | AL4: PENALTIES
A5: # | B5: =Score!$A$1 -> BOULDER COUNTY ROLLER DERBY / FLATIRON PHOENIXES | C5: JAMMER | D5: PIVOT | E5: BLOCKER | F5: TOTAL | G5: % JAMS SKATED | H5: POINTS | I5: PPJ | J5: LOST | K5: LEAD | L5: CALLED | M5: NO INITIAL TRIP | N5: STAR PASSES RECEIVED | O5: LEAD % | P5: LEAD +/- | Q5: AVERAGE LEAD +/- | R5: PTS FOR | S5: PTS AGAINST | T5: TOTAL +/- | U5: JAMMER +/- | V5: AVERAGE JAMMER +/- | W5: PIVOT +/- | X5: AVERAGE PIVOT +/- | Y5: BLOCK +/- | Z5: AVERAGE BLOCKER +/- | AA5: PACK +/- | AB5: AVERAGE PACK +/- | AC5: AVG +/- | AD5: VTAR PTS FOR | AE5: VTAR PTS AGAINST | AF5: VTAR TOTAL +/- | AG5: VTAR JAMMER AVG +/- | AH5: VTAR PIVOT AVG +/- | AI5: VTAR BLOCKER AVG +/- | AJ5: VTAR PACK AVG +/- | AK5: TOTAL VTAR AVG +/- | AL5: SKATERS PENALTY COUNT
A6: =IF(ISBLANK(IGRF!$B14),"",IGRF!$B14) -> 113 | B6: =IF(ISBLANK(IGRF!$C14),"",IGRF!$C14) -> Short Stack | C6: =IF(A6="","",SUM(LU!O9,LU!O108)) -> 3 | D6: =IF(A6="","",SUM(LU!D9,LU!D108)) -> 6 | E6: =IF(A6="","",SUM(LU!J9,LU!J108)) -> 10 | F6: =IF(A6="","",(SUM(C6:E6)-(SUMPRODUCT(--(Lineups!C$4:C$41=A6),--(Lineups!A$4:A$41="SP"))+SUMPRODUCT(--(Lineups!G$4:G$41=A6),--(Lineups!A$4:A$41="SP"))+SUMPRODUCT(--(Lineups!C$46:C$83=A6),--(Lineups!A$46:A$83="SP"))+SUMPRODUCT(--(Lineups!G$46:G$83=A6),--(Lineups!A$46:A$83="SP"))))) -> 17 | G6: =IF(OR(A6="",F6=0,LU!D$3+LU!D$102=0),"",F6/(LU!D$3+LU!D$102)) -> 0.38636364 | H6: =IF(OR(C6=0,A6=""),"",SK!D174) -> 0 | I6: =IF(OR(A6="",SK!E174="",SK!E174=0),"",H6/SK!E174) -> 0 | J6: =IF(OR(A6="",C6=0),"",SK!G174) -> 0 | K6: =IF(OR(A6="",C6=0),"",SK!H174) -> 0 | L6: =IF(OR(A6="",C6=0),"",SK!J174) -> 0 | M6: =IF(OR(A6="",C6=0),"",SK!L174) -> 1 | N6: =IF(OR(A6="",C6=0),"",SUMPRODUCT(--(Lineups!$A$4:$A$41="SP"),--(Lineups!$C$4:$C$41=A6))+SUMPRODUCT(--(Lineups!$A$46:$A$83="SP"),--(Lineups!$C$46:$C$83=A6))) -> 2 | O6: =IF(OR(A6="",C6="",(IF(C6="",0,C6)-IF(N6="",0,N6))=0),"",K6/(C6-N6)) -> 0 | P6: =IF(OR(A6="",C6=0),"",SK!I174) -> 0 | Q6: =IF(OR(A6="",C6=0,K6=0),"",P6/K6) | R6: =IF(OR(A6="",F6=0),"",SUM(LU!Q55,LU!Q154)) -> 57 | S6: =IF(OR(A6="",F6=0),"",SUM(LU!Q78,LU!Q177)) -> 121 | T6: =IF(OR(A6="",F6=0),"",SUM(LU!Q32,LU!Q131)) -> -64 | U6: =IF(OR(A6="",C6=0),"",SUM(LU!O32,LU!O131)) -> -7 | V6: =IF(OR(A6="",C6=0),"",U6/C6) -> -2.3333333 | W6: =IF(OR(A6="",D6=0),"",SUM(LU!D32,LU!D131)) -> -16 | X6: =IF(OR(A6="",D6=0),"",W6/D6) -> -2.6666667 | Y6: =IF(OR(A6="",E6=0),"",SUM(LU!J32,LU!J131)) -> -41 | Z6: =IF(OR(A6="",E6=0),"",Y6/E6) -> -4.1 | AA6: =IF(OR(A6="",AND(D6=0, E6=0)),"",SUM(LU!L32,LU!L131)) -> -57 | AB6: =IF(OR(A6="",AND(D6=0, E6=0)),"",AA6/(D6+E6)) -> -3.5625 | AC6: =IF(OR(A6="",F6=0),"",T6/F6) -> -3.7647059 | AD6: =IF(OR(A6="",F6=0,R$26="-",LU!$D$5=0),"",R6-R$26) -> 11.333333 | AE6: =IF(OR(A6="",F6=0,S$26="-",LU!$D$5=0),"",S6-S$26) -> 31 | AF6: =IF(OR(A6="",F6=0,AD6=""),"",AD6-AE6) -> -19.666667 | AG6: =IF(OR($A6="",C6=0),"",V6-V$26) -> 0.63825064 | AH6: =IF(OR($A6="",D6=0),"",X6-X$26) -> -2.1492063 | AI6: =IF(OR($A6="",E6=0),"",Z6-Z$26) -> -1.6761294 | AJ6: =IF(OR($A6="",AND(D6=0, E6=0)),"",AB6-AB$26) -> -0.98916946 | AK6: =IF(OR($A6="",AC6="",AC$26="-",LU!$D$5=0),"",AC6-AC$26) -> -0.84759983 | AL6: =IF(OR(A6="",F6=0),"",SUM(PT!U3,PT!U4)) -> 1
A7: =IF(ISBLANK(IGRF!$B15),"",IGRF!$B15) -> 114 | B7: =IF(ISBLANK(IGRF!$C15),"",IGRF!$C15) -> Cat Claus | C7: =IF(A7="","",SUM(LU!O10,LU!O109)) -> 0 | D7: =IF(A7="","",SUM(LU!D10,LU!D109)) -> 1 | E7: =IF(A7="","",SUM(LU!J10,LU!J109)) -> 18 | F7: =IF(A7="","",(SUM(C7:E7)-(SUMPRODUCT(--(Lineups!C$4:C$41=A7),--(Lineups!A$4:A$41="SP"))+SUMPRODUCT(--(Lineups!G$4:G$41=A7),--(Lineups!A$4:A$41="SP"))+SUMPRODUCT(--(Lineups!C$46:C$83=A7),--(Lineups!A$46:A$83="SP"))+SUMPRODUCT(--(Lineups!G$46:G$83=A7),--(Lineups!A$46:A$83="SP"))))) -> 19 | G7: =IF(OR(A7="",F7=0,LU!D$3+LU!D$102=0),"",F7/(LU!D$3+LU!D$102)) -> 0.43181818 | H7: =IF(OR(C7=0,A7=""),"",SK!D177) | I7: =IF(OR(A7="",SK!E177="",SK!E177=0),"",H7/SK!E177) | J7: =IF(OR(A7="",C7=0),"",SK!G177) | K7: =IF(OR(A7="",C7=0),"",SK!H177) | L7: =IF(OR(A7="",C7=0),"",SK!J177) | M7: =IF(OR(A7="",C7=0),"",SK!L177) | N7: =IF(OR(A7="",C7=0),"",SUMPRODUCT(--(Lineups!$A$4:$A$41="SP"),--(Lineups!$C$4:$C$41=A7))+SUMPRODUCT(--(Lineups!$A$46:$A$83="SP"),--(Lineups!$C$46:$C$83=A7))) | O7: =IF(OR(A7="",C7="",(IF(C7="",0,C7)-IF(N7="",0,N7))=0),"",K7/(C7-N7)) | P7: =IF(OR(A7="",C7=0),"",SK!I177) | Q7: =IF(OR(A7="",C7=0,K7=0),"",P7/K7) | R7: =IF(OR(A7="",F7=0),"",SUM(LU!Q56,LU!Q155)) -> 38 | S7: =IF(OR(A7="",F7=0),"",SUM(LU!Q79,LU!Q178)) -> 148 | T7: =IF(OR(A7="",F7=0),"",SUM(LU!Q33,LU!Q132)) -> -110 | U7: =IF(OR(A7="",C7=0),"",SUM(LU!O33,LU!O132)) | V7: =IF(OR(A7="",C7=0),"",U7/C7) | W7: =IF(OR(A7="",D7=0),"",SUM(LU!D33,LU!D132)) -> 6 | X7: =IF(OR(A7="",D7=0),"",W7/D7) -> 6 | Y7: =IF(OR(A7="",E7=0),"",SUM(LU!J33,LU!J132)) -> -116 | Z7: =IF(OR(A7="",E7=0),"",Y7/E7) -> -6.4444444 | AA7: =IF(OR(A7="",AND(D7=0, E7=0)),"",SUM(LU!L33,LU!L132)) -> -110 | AB7: =IF(OR(A7="",AND(D7=0, E7=0)),"",AA7/(D7+E7)) -> -5.7894737 | AC7: =IF(OR(A7="",F7="",F7=0),"",T7/F7) -> -5.7894737 | AD7: =IF(OR(A7="",F7=0,R$26="-",LU!$D$5=0),"",R7-R$26) -> -7.6666667 | AE7: =IF(OR(A7="",F7=0,S$26="-",LU!$D$5=0),"",S7-S$26) -> 58 | AF7: =IF(OR(A7="",F7=0,AD7=""),"",AD7-AE7) -> -65.666667 | AG7: =IF(OR($A7="",C7=0),"",V7-V$26) | AH7: =IF(OR($A7="",D7=0),"",X7-X$26) -> 6.5174603 | AI7: =IF(OR($A7="",E7=0),"",Z7-Z$26) -> -4.0205738 | AJ7: =IF(OR($A7="",AND(D7=0, E7=0)),"",AB7-AB$26) -> -3.2161431 | AK7: =IF(OR($A7="",AC7="",AC$26="-",LU!$D$5=0),"",AC7-AC$26) -> -2.8723676 | AL7: =IF(OR(A7="",F7=0),"",SUM(PT!U5,PT!U6)) -> 3
A8: =IF(ISBLANK(IGRF!$B16),"",IGRF!$B16) -> 1190 | B8: =IF(ISBLANK(IGRF!$C16),"",IGRF!$C16) -> Rickashanaynay | C8: =IF(A8="","",SUM(LU!O11,LU!O110)) -> 9 | D8: =IF(A8="","",SUM(LU!D11,LU!D110)) -> 0 | E8: =IF(A8="","",SUM(LU!J11,LU!J110)) -> 1 | F8: =IF(A8="","",(SUM(C8:E8)-(SUMPRODUCT(--(Lineups!C$4:C$41=A8),--(Lineups!A$4:A$41="SP"))+SUMPRODUCT(--(Lineups!G$4:G$41=A8),--(Lineups!A$4:A$41="SP"))+SUMPRODUCT(--(Lineups!C$46:C$83=A8),--(Lineups!A$46:A$83="SP"))+SUMPRODUCT(--(Lineups!G$46:G$83=A8),--(Lineups!A$46:A$83="SP"))))) -> 9 | G8: =IF(OR(A8="",F8=0,LU!D$3+LU!D$102=0),"",F8/(LU!D$3+LU!D$102)) -> 0.20454545 | H8: =IF(OR(C8=0,A8=""),"",SK!D180) -> 13 | I8: =IF(OR(A8="",SK!E180="",SK!E180=0),"",H8/SK!E180) -> 1.4444444 | J8: =IF(OR(A8="",C8=0),"",SK!G180) -> 0 | K8: =IF(OR(A8="",C8=0),"",SK!H180) -> 3 | L8: =IF(OR(A8="",C8=0),"",SK!J180) -> 3 | M8: =IF(OR(A8="",C8=0),"",SK!L180) -> 2 | N8: =IF(OR(A8="",C8=0),"",SUMPRODUCT(--(Lineups!$A$4:$A$41="SP"),--(Lineups!$C$4:$C$41=A8))+SUMPRODUCT(--(Lineups!$A$46:$A$83="SP"),--(Lineups!$C$46:$C$83=A8))) -> 0 | O8: =IF(OR(A8="",C8="",(IF(C8="",0,C8)-IF(N8="",0,N8))=0),"",K8/(C8-N8)) -> 0.33333333 | P8: =IF(OR(A8="",C8=0),"",SK!I180) -> 6 | Q8: =IF(OR(A8="",C8=0,K8=0),"",P8/K8) -> 2 | R8: =IF(OR(A8="",F8=0),"",SUM(LU!Q57,LU!Q156)) -> 13 | S8: =IF(OR(A8="",F8=0),"",SUM(LU!Q80,LU!Q179)) -> 32 | T8: =IF(OR(A8="",F8=0),"",SUM(LU!Q34,LU!Q133)) -> -19 | U8: =IF(OR(A8="",C8=0),"",SUM(LU!O34,LU!O133)) -> -19 | V8: =IF(OR(A8="",C8=0),"",U8/C8) -> -2.1111111 | W8: =IF(OR(A8="",D8=0),"",SUM(LU!D34,LU!D133)) | X8: =IF(OR(A8="",D8=0),"",W8/D8) | Y8: =IF(OR(A8="",E8=0),"",SUM(LU!J34,LU!J133)) -> 0 | Z8: =IF(OR(A8="",E8=0),"",Y8/E8) -> 0 | AA8: =IF(OR(A8="",AND(D8=0, E8=0)),"",SUM(LU!L34,LU!L133)) -> 0 | AB8: =IF(OR(A8="",AND(D8=0, E8=0)),"",AA8/(D8+E8)) -> 0 | AC8: =IF(OR(A8="",F8="",F8=0),"",T8/F8) -> -2.1111111 | AD8: =IF(OR(A8="",F8=0,R$26="-",LU!$D$5=0),"",R8-R$26) -> -32.666667 | AE8: =IF(OR(A8="",F8=0,S$26="-",LU!$D$5=0),"",S8-S$26) -> -58 | AF8: =IF(OR(A8="",F8=0,AD8=""),"",AD8-AE8) -> 25.333333 | AG8: =IF(OR($A8="",C8=0),"",V8-V$26) -> 0.86047286 | AH8: =IF(OR($A8="",D8=0),"",X8-X$26) | AI8: =IF(OR($A8="",E8=0),"",Z8-Z$26) -> 2.4238706 | AJ8: =IF(OR($A8="",AND(D8=0, E8=0)),"",AB8-AB$26) -> 2.5733305 | AK8: =IF(OR($A8="",AC8="",AC$26="-",LU!$D$5=0),"",AC8-AC$26) -> 0.80599494 | AL8: =IF(OR(A8="",F8=0),"",SUM(PT!U7,PT!U8)) -> 0
A9: =IF(ISBLANK(IGRF!$B17),"",IGRF!$B17) -> 213 | B9: =IF(ISBLANK(IGRF!$C17),"",IGRF!$C17) -> Primeval | C9: =IF(A9="","",SUM(LU!O12,LU!O111)) -> 0 | D9: =IF(A9="","",SUM(LU!D12,LU!D111)) -> 1 | E9: =IF(A9="","",SUM(LU!J12,LU!J111)) -> 19 | F9: =IF(A9="","",(SUM(C9:E9)-(SUMPRODUCT(--(Lineups!C$4:C$41=A9),--(Lineups!A$4:A$41="SP"))+SUMPRODUCT(--(Lineups!G$4:G$41=A9),--(Lineups!A$4:A$41="SP"))+SUMPRODUCT(--(Lineups!C$46:C$83=A9),--(Lineups!A$46:A$83="SP"))+SUMPRODUCT(--(Lineups!G$46:G$83=A9),--(Lineups!A$46:A$83="SP"))))) -> 20 | G9: =IF(OR(A9="",F9=0,LU!D$3+LU!D$102=0),"",F9/(LU!D$3+LU!D$102)) -> 0.45454545 | H9: =IF(OR(C9=0,A9=""),"",SK!D183) | I9: =IF(OR(A9="",SK!E183="",SK!E183=0),"",H9/SK!E183) | J9: =IF(OR(A9="",C9=0),"",SK!G183) | K9: =IF(OR(A9="",C9=0),"",SK!H183) | L9: =IF(OR(A9="",C9=0),"",SK!J183) | M9: =IF(OR(A9="",C9=0),"",SK!L183) | N9: =IF(OR(A9="",C9=0),"",SUMPRODUCT(--(Lineups!$A$4:$A$41="SP"),--(Lineups!$C$4:$C$41=A9))+SUMPRODUCT(--(Lineups!$A$46:$A$83="SP"),--(Lineups!$C$46:$C$83=A9))) | O9: =IF(OR(A9="",C9="",(IF(C9="",0,C9)-IF(N9="",0,N9))=0),"",K9/(C9-N9)) | P9: =IF(OR(A9="",C9=0),"",SK!I183) | Q9: =IF(OR(A9="",C9=0,K9=0),"",P9/K9) | R9: =IF(OR(A9="",F9=0),"",SUM(LU!Q58,LU!Q157)) -> 61 | S9: =IF(OR(A9="",F9=0),"",SUM(LU!Q81,LU!Q180)) -> 107 | T9: =IF(OR(A9="",F9=0),"",SUM(LU!Q35,LU!Q134)) -> -46 | U9: =IF(OR(A9="",C9=0),"",SUM(LU!O35,LU!O134)) | V9: =IF(OR(A9="",C9=0),"",U9/C9) | W9: =IF(OR(A9="",D9=0),"",SUM(LU!D35,LU!D134)) -> 4 | X9: =IF(OR(A9="",D9=0),"",W9/D9) -> 4 | Y9: =IF(OR(A9="",E9=0),"",SUM(LU!J35,LU!J134)) -> -50 | Z9: =IF(OR(A9="",E9=0),"",Y9/E9) -> -2.6315789 | AA9: =IF(OR(A9="",AND(D9=0, E9=0)),"",SUM(LU!L35,LU!L134)) -> -46 | AB9: =IF(OR(A9="",AND(D9=0, E9=0)),"",AA9/(D9+E9)) -> -2.3 | AC9: =IF(OR(A9="",F9="",F9=0),"",T9/F9) -> -2.3 | AD9: =IF(OR(A9="",F9=0,R$26="-",LU!$D$5=0),"",R9-R$26) -> 15.333333 | AE9: =IF(OR(A9="",F9=0,S$26="-",LU!$D$5=0),"",S9-S$26) -> 17 | AF9: =IF(OR(A9="",F9=0,AD9=""),"",AD9-AE9) -> -1.6666667 | AG9: =IF(OR($A9="",C9=0),"",V9-V$26) | AH9: =IF(OR($A9="",D9=0),"",X9-X$26) -> 4.5174603 | AI9: =IF(OR($A9="",E9=0),"",Z9-Z$26) -> -0.20770831 | AJ9: =IF(OR($A9="",AND(D9=0, E9=0)),"",AB9-AB$26) -> 0.27333054 | AK9: =IF(OR($A9="",AC9="",AC$26="-",LU!$D$5=0),"",AC9-AC$26) -> 0.61710605 | AL9: =IF(OR(A9="",F9=0),"",SUM(PT!U9,PT!U10)) -> 2
A10: =IF(ISBLANK(IGRF!$B18),"",IGRF!$B18) -> 22 | B10: =IF(ISBLANK(IGRF!$C18),"",IGRF!$C18) -> Penelope Bruise | C10: =IF(A10="","",SUM(LU!O13,LU!O112)) -> 0 | D10: =IF(A10="","",SUM(LU!D13,LU!D112)) -> 15 | E10: =IF(A10="","",SUM(LU!J13,LU!J112)) -> 2 | F10: =IF(A10="","",(SUM(C10:E10)-(SUMPRODUCT(--(Lineups!C$4:C$41=A10),--(Lineups!A$4:A$41="SP"))+SUMPRODUCT(--(Lineups!G$4:G$41=A10),--(Lineups!A$4:A$41="SP"))+SUMPRODUCT(--(Lineups!C$46:C$83=A10),--(Lineups!A$46:A$83="SP"))+SUMPRODUCT(--(Lineups!G$46:G$83=A10),--(Lineups!A$46:A$83="SP"))))) -> 17 | G10: =IF(OR(A10="",F10=0,LU!D$3+LU!D$102=0),"",F10/(LU!D$3+LU!D$102)) -> 0.38636364 | H10: =IF(OR(C10=0,A10=""),"",SK!D186) | I10: =IF(OR(A10="",SK!E186="",SK!E186=0),"",H10/SK!E186) | J10: =IF(OR(A10="",C10=0),"",SK!G186) | K10: =IF(OR(A10="",C10=0),"",SK!H186) | L10: =IF(OR(A10="",C10=0),"",SK!J186) | M10: =IF(OR(A10="",C10=0),"",SK!L186) | N10: =IF(OR(A10="",C10=0),"",SUMPRODUCT(--(Lineups!$A$4:$A$41="SP"),--(Lineups!$C$4:$C$41=A10))+SUMPRODUCT(--(Lineups!$A$46:$A$83="SP"),--(Lineups!$C$46:$C$83=A10))) | O10: =IF(OR(A10="",C10="",(IF(C10="",0,C10)-IF(N10="",0,N10))=0),"",K10/(C10-N10)) | P10: =IF(OR(A10="",C10=0),"",SK!I186) | Q10: =IF(OR(A10="",C10=0,K10=0),"",P10/K10) | R10: =IF(OR(A10="",F10=0),"",SUM(LU!Q59,LU!Q158)) -> 53 | S10: =IF(OR(A10="",F10=0),"",SUM(LU!Q82,LU!Q181)) -> 76 | T10: =IF(OR(A10="",F10=0),"",SUM(LU!Q36,LU!Q135)) -> -23 | U10: =IF(OR(A10="",C10=0),"",SUM(LU!O36,LU!O135)) | V10: =IF(OR(A10="",C10=0),"",U10/C10) | W10: =IF(OR(A10="",D10=0),"",SUM(LU!D36,LU!D135)) -> -11 | X10: =IF(OR(A10="",D10=0),"",W10/D10) -> -0.73333333 | Y10: =IF(OR(A10="",E10=0),"",SUM(LU!J36,LU!J135)) -> -12 | Z10: =IF(OR(A10="",E10=0),"",Y10/E10) -> -6 | AA10: =IF(OR(A10="",AND(D10=0, E10=0)),"",SUM(LU!L36,LU!L135)) -> -23 | AB10: =IF(OR(A10="",AND(D10=0, E10=0)),"",AA10/(D10+E10)) -> -1.3529412 | AC10: =IF(OR(A10="",F10="",F10=0),"",T10/F10) -> -1.3529412 | AD10: =IF(OR(A10="",F10=0,R$26="-",LU!$D$5=0),"",R10-R$26) -> 7.3333333 | AE10: =IF(OR(A10="",F10=0,S$26="-",LU!$D$5=0),"",S10-S$26) -> -14 | AF10: =IF(OR(A10="",F10=0,AD10=""),"",AD10-AE10) -> 21.333333 | AG10: =IF(OR($A10="",C10=0),"",V10-V$26) | AH10: =IF(OR($A10="",D10=0),"",X10-X$26) -> -0.21587302 | AI10: =IF(OR($A10="",E10=0),"",Z10-Z$26) -> -3.5761294 | AJ10: =IF(OR($A10="",AND(D10=0, E10=0)),"",AB10-AB$26) -> 1.2203894 | AK10: =IF(OR($A10="",AC10="",AC$26="-",LU!$D$5=0),"",AC10-AC$26) -> 1.5641649 | AL10: =IF(OR(A10="",F10=0),"",SUM(PT!U11,PT!U12)) -> 0
A11: =IF(ISBLANK(IGRF!$B19),"",IGRF!$B19) -> 33 | B11: =IF(ISBLANK(IGRF!$C19),"",IGRF!$C19) -> Ivy Profen | C11: =IF(A11="","",SUM(LU!O14,LU!O113)) -> 1 | D11: =IF(A11="","",SUM(LU!D14,LU!D113)) -> 18 | E11: =IF(A11="","",SUM(LU!J14,LU!J113)) -> 3 | F11: =IF(A11="","",(SUM(C11:E11)-(SUMPRODUCT(--(Lineups!C$4:C$41=A11),--(Lineups!A$4:A$41="SP"))+SUMPRODUCT(--(Lineups!G$4:G$41=A11),--(Lineups!A$4:A$41="SP"))+SUMPRODUCT(--(Lineups!C$46:C$83=A11),--(Lineups!A$46:A$83="SP"))+SUMPRODUCT(--(Lineups!G$46:G$83=A11),--(Lineups!A$46:A$83="SP"))))) -> 21 | G11: =IF(OR(A11="",F11=0,LU!D$3+LU!D$102=0),"",F11/(LU!D$3+LU!D$102)) -> 0.47727273 | H11: =IF(OR(C11=0,A11=""),"",SK!D189) -> 0 | I11: =IF(OR(A11="",SK!E189="",SK!E189=0),"",H11/SK!E189) -> 0 | J11: =IF(OR(A11="",C11=0),"",SK!G189) -> 0 | K11: =IF(OR(A11="",C11=0),"",SK!H189) -> 0 | L11: =IF(OR(A11="",C11=0),"",SK!J189) -> 0 | M11: =IF(OR(A11="",C11=0),"",SK!L189) -> 0 | N11: =IF(OR(A11="",C11=0),"",SUMPRODUCT(--(Lineups!$A$4:$A$41="SP"),--(Lineups!$C$4:$C$41=A11))+SUMPRODUCT(--(Lineups!$A$46:$A$83="SP"),--(Lineups!$C$46:$C$83=A11))) -> 1 | O11: =IF(OR(A11="",C11="",(IF(C11="",0,C11)-IF(N11="",0,N11))=0),"",K11/(C11-N11)) | P11: =IF(OR(A11="",C11=0),"",SK!I189) -> 0 | Q11: =IF(OR(A11="",C11=0,K11=0),"",P11/K11) | R11: =IF(OR(A11="",F11=0),"",SUM(LU!Q60,LU!Q159)) -> 53 | S11: =IF(OR(A11="",F11=0),"",SUM(LU!Q83,LU!Q182)) -> 162 | T11: =IF(OR(A11="",F11=0),"",SUM(LU!Q37,LU!Q136)) -> -109 | U11: =IF(OR(A11="",C11=0),"",SUM(LU!O37,LU!O136)) -> 0 | V11: =IF(OR(A11="",C11=0),"",U11/C11) -> 0 | W11: =IF(OR(A11="",D11=0),"",SUM(LU!D37,LU!D136)) -> -112 | X11: =IF(OR(A11="",D11=0),"",W11/D11) -> -6.2222222 | Y11: =IF(OR(A11="",E11=0),"",SUM(LU!J37,LU!J136)) -> 3 | Z11: =IF(OR(A11="",E11=0),"",Y11/E11) -> 1 | AA11: =IF(OR(A11="",AND(D11=0, E11=0)),"",SUM(LU!L37,LU!L136)) -> -109 | AB11: =IF(OR(A11="",AND(D11=0, E11=0)),"",AA11/(D11+E11)) -> -5.1904762 | AC11: =IF(OR(A11="",F11="",F11=0),"",T11/F11) -> -5.1904762 | AD11: =IF(OR(A11="",F11=0,R$26="-",LU!$D$5=0),"",R11-R$26) -> 7.3333333 | AE11: =IF(OR(A11="",F11=0,S$26="-",LU!$D$5=0),"",S11-S$26) -> 72 | AF11: =IF(OR(A11="",F11=0,AD11=""),"",AD11-AE11) -> -64.666667 | AG11: =IF(OR($A11="",C11=0),"",V11-V$26) -> 2.971584 | AH11: =IF(OR($A11="",D11=0),"",X11-X$26) -> -5.7047619 | AI11: =IF(OR($A11="",E11=0),"",Z11-Z$26) -> 3.4238706 | AJ11: =IF(OR($A11="",AND(D11=0, E11=0)),"",AB11-AB$26) -> -2.6171456 | AK11: =IF(OR($A11="",AC11="",AC$26="-",LU!$D$5=0),"",AC11-AC$26) -> -2.2733701 | AL11: =IF(OR(A11="",F11=0),"",SUM(PT!U13,PT!U14)) -> 3
A12: =IF(ISBLANK(IGRF!$B20),"",IGRF!$B20) -> 333 | B12: =IF(ISBLANK(IGRF!$C20),"",IGRF!$C20) -> Honey Badger | C12: =IF(A12="","",SUM(LU!O15,LU!O114)) -> 13 | D12: =IF(A12="","",SUM(LU!D15,LU!D114)) -> 0 | E12: =IF(A12="","",SUM(LU!J15,LU!J114)) -> 0 | F12: =IF(A12="","",(SUM(C12:E12)-(SUMPRODUCT(--(Lineups!C$4:C$41=A12),--(Lineups!A$4:A$41="SP"))+SUMPRODUCT(--(Lineups!G$4:G$41=A12),--(Lineups!A$4:A$41="SP"))+SUMPRODUCT(--(Lineups!C$46:C$83=A12),--(Lineups!A$46:A$83="SP"))+SUMPRODUCT(--(Lineups!G$46:G$83=A12),--(Lineups!A$46:A$83="SP"))))) -> 13 | G12: =IF(OR(A12="",F12=0,LU!D$3+LU!D$102=0),"",F12/(LU!D$3+LU!D$102)) -> 0.29545455 | H12: =IF(OR(C12=0,A12=""),"",SK!D192) -> 35 | I12: =IF(OR(A12="",SK!E192="",SK!E192=0),"",H12/SK!E192) -> 2.6923077 | J12: =IF(OR(A12="",C12=0),"",SK!G192) -> 1 | K12: =IF(OR(A12="",C12=0),"",SK!H192) -> 4 | L12: =IF(OR(A12="",C12=0),"",SK!J192) -> 2 | M12: =IF(OR(A12="",C12=0),"",SK!L192) -> 2 | N12: =IF(OR(A12="",C12=0),"",SUMPRODUCT(--(Lineups!$A$4:$A$41="SP"),--(Lineups!$C$4:$C$41=A12))+SUMPRODUCT(--(Lineups!$A$46:$A$83="SP"),--(Lineups!$C$46:$C$83=A12))) -> 0 | O12: =IF(OR(A12="",C12="",(IF(C12="",0,C12)-IF(N12="",0,N12))=0),"",K12/(C12-N12)) -> 0.30769231 | P12: =IF(OR(A12="",C12=0),"",SK!I192) -> 1 | Q12: =IF(OR(A12="",C12=0,K12=0),"",P12/K12) -> 0.25 | R12: =IF(OR(A12="",F12=0),"",SUM(LU!Q61,LU!Q160)) -> 35 | S12: =IF(OR(A12="",F12=0),"",SUM(LU!Q84,LU!Q183)) -> 94 | T12: =IF(OR(A12="",F12=0),"",SUM(LU!Q38,LU!Q137)) -> -59 | U12: =IF(OR(A12="",C12=0),"",SUM(LU!O38,LU!O137)) -> -59 | V12: =IF(OR(A12="",C12=0),"",U12/C12) -> -4.5384615 | W12: =IF(OR(A12="",D12=0),"",SUM(LU!D38,LU!D137)) | X12: =IF(OR(A12="",D12=0),"",W12/D12) | Y12: =IF(OR(A12="",E12=0),"",SUM(LU!J38,LU!J137)) | Z12: =IF(OR(A12="",E12=0),"",Y12/E12) | AA12: =IF(OR(A12="",AND(D12=0, E12=0)),"",SUM(LU!L38,LU!L137)) | AB12: =IF(OR(A12="",AND(D12=0, E12=0)),"",AA12/(D12+E12)) | AC12: =IF(OR(A12="",F12="",F12=0),"",T12/F12) -> -4.5384615 | AD12: =IF(OR(A12="",F12=0,R$26="-",LU!$D$5=0),"",R12-R$26) -> -10.666667 | AE12: =IF(OR(A12="",F12=0,S$26="-",LU!$D$5=0),"",S12-S$26) -> 4 | AF12: =IF(OR(A12="",F12=0,AD12=""),"",AD12-AE12) -> -14.666667 | AG12: =IF(OR($A12="",C12=0),"",V12-V$26) -> -1.5668776 | AH12: =IF(OR($A12="",D12=0),"",X12-X$26) | AI12: =IF(OR($A12="",E12=0),"",Z12-Z$26) | AJ12: =IF(OR($A12="",AND(D12=0, E12=0)),"",AB12-AB$26) | AK12: =IF(OR($A12="",AC12="",AC$26="-",LU!$D$5=0),"",AC12-AC$26) -> -1.6213555 | AL12: =IF(OR(A12="",F12=0),"",SUM(PT!U15,PT!U16)) -> 6
A13: =IF(ISBLANK(IGRF!$B21),"",IGRF!$B21) -> 393 | B13: =IF(ISBLANK(IGRF!$C21),"",IGRF!$C21) -> Miss EDventure | C13: =IF(A13="","",SUM(LU!O16,LU!O115)) -> 0 | D13: =IF(A13="","",SUM(LU!D16,LU!D115)) -> 0 | E13: =IF(A13="","",SUM(LU!J16,LU!J115)) -> 0 | F13: =IF(A13="","",(SUM(C13:E13)-(SUMPRODUCT(--(Lineups!C$4:C$41=A13),--(Lineups!A$4:A$41="SP"))+SUMPRODUCT(--(Lineups!G$4:G$41=A13),--(Lineups!A$4:A$41="SP"))+SUMPRODUCT(--(Lineups!C$46:C$83=A13),--(Lineups!A$46:A$83="SP"))+SUMPRODUCT(--(Lineups!G$46:G$83=A13),--(Lineups!A$46:A$83="SP"))))) -> 0 | G13: =IF(OR(A13="",F13=0,LU!D$3+LU!D$102=0),"",F13/(LU!D$3+LU!D$102)) | H13: =IF(OR(C13=0,A13=""),"",SK!D195) | I13: =IF(OR(A13="",SK!E195="",SK!E195=0),"",H13/SK!E195) | J13: =IF(OR(A13="",C13=0),"",SK!G195) | K13: =IF(OR(A13="",C13=0),"",SK!H195) | L13: =IF(OR(A13="",C13=0),"",SK!J195) | M13: =IF(OR(A13="",C13=0),"",SK!L195) | N13: =IF(OR(A13="",C13=0),"",SUMPRODUCT(--(Lineups!$A$4:$A$41="SP"),--(Lineups!$C$4:$C$41=A13))+SUMPRODUCT(--(Lineups!$A$46:$A$83="SP"),--(Lineups!$C$46:$C$83=A13))) | O13: =IF(OR(A13="",C13="",(IF(C13="",0,C13)-IF(N13="",0,N13))=0),"",K13/(C13-N13)) | P13: =IF(OR(A13="",C13=0),"",SK!I195) | Q13: =IF(OR(A13="",C13=0,K13=0),"",P13/K13) | R13: =IF(OR(A13="",F13=0),"",SUM(LU!Q62,LU!Q161)) | S13: =IF(OR(A13="",F13=0),"",SUM(LU!Q85,LU!Q184)) | T13: =IF(OR(A13="",F13=0),"",SUM(LU!Q39,LU!Q138)) | U13: =IF(OR(A13="",C13=0),"",SUM(LU!O39,LU!O138)) | V13: =IF(OR(A13="",C13=0),"",U13/C13) | W13: =IF(OR(A13="",D13=0),"",SUM(LU!D39,LU!D138)) | X13: =IF(OR(A13="",D13=0),"",W13/D13) | Y13: =IF(OR(A13="",E13=0),"",SUM(LU!J39,LU!J138)) | Z13: =IF(OR(A13="",E13=0),"",Y13/E13) | AA13: =IF(OR(A13="",AND(D13=0, E13=0)),"",SUM(LU!L39,LU!L138)) | AB13: =IF(OR(A13="",AND(D13=0, E13=0)),"",AA13/(D13+E13)) | AC13: =IF(OR(A13="",F13="",F13=0),"",T13/F13) | AD13: =IF(OR(A13="",F13=0,R$26="-",LU!$D$5=0),"",R13-R$26) | AE13: =IF(OR(A13="",F13=0,S$26="-",LU!$D$5=0),"",S13-S$26) | AF13: =IF(OR(A13="",F13=0,AD13=""),"",AD13-AE13) | AG13: =IF(OR($A13="",C13=0),"",V13-V$26) | AH13: =IF(OR($A13="",D13=0),"",X13-X$26) | AI13: =IF(OR($A13="",E13=0),"",Z13-Z$26) | AJ13: =IF(OR($A13="",AND(D13=0, E13=0)),"",AB13-AB$26) | AK13: =IF(OR($A13="",AC13="",AC$26="-",LU!$D$5=0),"",AC13-AC$26) | AL13: =IF(OR(A13="",F13=0),"",SUM(PT!U17,PT!U18))
A14: =IF(ISBLANK(IGRF!$B22),"",IGRF!$B22) -> 504 | B14: =IF(ISBLANK(IGRF!$C22),"",IGRF!$C22) -> Fleur de Beast | C14: =IF(A14="","",SUM(LU!O17,LU!O116)) -> 0 | D14: =IF(A14="","",SUM(LU!D17,LU!D116)) -> 0 | E14: =IF(A14="","",SUM(LU!J17,LU!J116)) -> 13 | F14: =IF(A14="","",(SUM(C14:E14)-(SUMPRODUCT(--(Lineups!C$4:C$41=A14),--(Lineups!A$4:A$41="SP"))+SUMPRODUCT(--(Lineups!G$4:G$41=A14),--(Lineups!A$4:A$41="SP"))+SUMPRODUCT(--(Lineups!C$46:C$83=A14),--(Lineups!A$46:A$83="SP"))+SUMPRODUCT(--(Lineups!G$46:G$83=A14),--(Lineups!A$46:A$83="SP"))))) -> 13 | G14: =IF(OR(A14="",F14=0,LU!D$3+LU!D$102=0),"",F14/(LU!D$3+LU!D$102)) -> 0.29545455 | H14: =IF(OR(C14=0,A14=""),"",SK!D198) | I14: =IF(OR(A14="",SK!E198="",SK!E198=0),"",H14/SK!E198) | J14: =IF(OR(A14="",C14=0),"",SK!G198) | K14: =IF(OR(A14="",C14=0),"",SK!H198) | L14: =IF(OR(A14="",C14=0),"",SK!J198) | M14: =IF(OR(A14="",C14=0),"",SK!L198) | N14: =IF(OR(A14="",C14=0),"",SUMPRODUCT(--(Lineups!$A$4:$A$41="SP"),--(Lineups!$C$4:$C$41=A14))+SUMPRODUCT(--(Lineups!$A$46:$A$83="SP"),--(Lineups!$C$46:$C$83=A14))) | O14: =IF(OR(A14="",C14="",(IF(C14="",0,C14)-IF(N14="",0,N14))=0),"",K14/(C14-N14)) | P14: =IF(OR(A14="",C14=0),"",SK!I198) | Q14: =IF(OR(A14="",C14=0,K14=0),"",P14/K14) | R14: =IF(OR(A14="",F14=0),"",SUM(LU!Q63,LU!Q162)) -> 44 | S14: =IF(OR(A14="",F14=0),"",SUM(LU!Q86,LU!Q185)) -> 103 | T14: =IF(OR(A14="",F14=0),"",SUM(LU!Q40,LU!Q139)) -> -59 | U14: =IF(OR(A14="",C14=0),"",SUM(LU!O40,LU!O139)) | V14: =IF(OR(A14="",C14=0),"",U14/C14) | W14: =IF(OR(A14="",D14=0),"",SUM(LU!D40,LU!D139)) | X14: =IF(OR(A14="",D14=0),"",W14/D14) | Y14: =IF(OR(A14="",E14=0),"",SUM(LU!J40,LU!J139)) -> -59 | Z14: =IF(OR(A14="",E14=0),"",Y14/E14) -> -4.5384615 | AA14: =IF(OR(A14="",AND(D14=0, E14=0)),"",SUM(LU!L40,LU!L139)) -> -59 | AB14: =IF(OR(A14="",AND(D14=0, E14=0)),"",AA14/(D14+E14)) -> -4.5384615 | AC14: =IF(OR(A14="",F14="",F14=0),"",T14/F14) -> -4.5384615 | AD14: =IF(OR(A14="",F14=0,R$26="-",LU!$D$5=0),"",R14-R$26) -> -1.6666667 | AE14: =IF(OR(A14="",F14=0,S$26="-",LU!$D$5=0),"",S14-S$26) -> 13 | AF14: =IF(OR(A14="",F14=0,AD14=""),"",AD14-AE14) -> -14.666667 | AG14: =IF(OR($A14="",C14=0),"",V14-V$26) | AH14: =IF(OR($A14="",D14=0),"",X14-X$26) | AI14: =IF(OR($A14="",E14=0),"",Z14-Z$26) -> -2.1145909 | AJ14: =IF(OR($A14="",AND(D14=0, E14=0)),"",AB14-AB$26) -> -1.965131 | AK14: =IF(OR($A14="",AC14="",AC$26="-",LU!$D$5=0),"",AC14-AC$26) -> -1.6213555 | AL14: =IF(OR(A14="",F14=0),"",SUM(PT!U19,PT!U20)) -> 1
A15: =IF(ISBLANK(IGRF!$B23),"",IGRF!$B23) -> 69 | B15: =IF(ISBLANK(IGRF!$C23),"",IGRF!$C23) -> Jungla | C15: =IF(A15="","",SUM(LU!O18,LU!O117)) -> 0 | D15: =IF(A15="","",SUM(LU!D18,LU!D117)) -> 0 | E15: =IF(A15="","",SUM(LU!J18,LU!J117)) -> 16 | F15: =IF(A15="","",(SUM(C15:E15)-(SUMPRODUCT(--(Lineups!C$4:C$41=A15),--(Lineups!A$4:A$41="SP"))+SUMPRODUCT(--(Lineups!G$4:G$41=A15),--(Lineups!A$4:A$41="SP"))+SUMPRODUCT(--(Lineups!C$46:C$83=A15),--(Lineups!A$46:A$83="SP"))+SUMPRODUCT(--(Lineups!G$46:G$83=A15),--(Lineups!A$46:A$83="SP"))))) -> 16 | G15: =IF(OR(A15="",F15=0,LU!D$3+LU!D$102=0),"",F15/(LU!D$3+LU!D$102)) -> 0.36363636 | H15: =IF(OR(C15=0,A15=""),"",SK!D201) | I15: =IF(OR(A15="",SK!E201="",SK!E201=0),"",H15/SK!E201) | J15: =IF(OR(A15="",C15=0),"",SK!G201) | K15: =IF(OR(A15="",C15=0),"",SK!H201) | L15: =IF(OR(A15="",C15=0),"",SK!J201) | M15: =IF(OR(A15="",C15=0),"",SK!L201) | N15: =IF(OR(A15="",C15=0),"",SUMPRODUCT(--(Lineups!$A$4:$A$41="SP"),--(Lineups!$C$4:$C$41=A15))+SUMPRODUCT(--(Lineups!$A$46:$A$83="SP"),--(Lineups!$C$46:$C$83=A15))) | O15: =IF(OR(A15="",C15="",(IF(C15="",0,C15)-IF(N15="",0,N15))=0),"",K15/(C15-N15)) | P15: =IF(OR(A15="",C15=0),"",SK!I201) | Q15: =IF(OR(A15="",C15=0,K15=0),"",P15/K15) | R15: =IF(OR(A15="",F15=0),"",SUM(LU!Q64,LU!Q163)) -> 38 | S15: =IF(OR(A15="",F15=0),"",SUM(LU!Q87,LU!Q186)) -> 80 | T15: =IF(OR(A15="",F15=0),"",SUM(LU!Q41,LU!Q140)) -> -42 | U15: =IF(OR(A15="",C15=0),"",SUM(LU!O41,LU!O140)) | V15: =IF(OR(A15="",C15=0),"",U15/C15) | W15: =IF(OR(A15="",D15=0),"",SUM(LU!D41,LU!D140)) | X15: =IF(OR(A15="",D15=0),"",W15/D15) | Y15: =IF(OR(A15="",E15=0),"",SUM(LU!J41,LU!J140)) -> -42 | Z15: =IF(OR(A15="",E15=0),"",Y15/E15) -> -2.625 | AA15: =IF(OR(A15="",AND(D15=0, E15=0)),"",SUM(LU!L41,LU!L140)) -> -42 | AB15: =IF(OR(A15="",AND(D15=0, E15=0)),"",AA15/(D15+E15)) -> -2.625 | AC15: =IF(OR(A15="",F15="",F15=0),"",T15/F15) -> -2.625 | AD15: =IF(OR(A15="",F15=0,R$26="-",LU!$D$5=0),"",R15-R$26) -> -7.6666667 | AE15: =IF(OR(A15="",F15=0,S$26="-",LU!$D$5=0),"",S15-S$26) -> -10 | AF15: =IF(OR(A15="",F15=0,AD15=""),"",AD15-AE15) -> 2.3333333 | AG15: =IF(OR($A15="",C15=0),"",V15-V$26) | AH15: =IF(OR($A15="",D15=0),"",X15-X$26) | AI15: =IF(OR($A15="",E15=0),"",Z15-Z$26) -> -0.20112936 | AJ15: =IF(OR($A15="",AND(D15=0, E15=0)),"",AB15-AB$26) -> -0.051669459 | AK15: =IF(OR($A15="",AC15="",AC$26="-",LU!$D$5=0),"",AC15-AC$26) -> 0.29210605 | AL15: =IF(OR(A15="",F15=0),"",SUM(PT!U21,PT!U22)) -> 2
A16: =IF(ISBLANK(IGRF!$B24),"",IGRF!$B24) -> 7 | B16: =IF(ISBLANK(IGRF!$C24),"",IGRF!$C24) -> Freddie Mercury Poisoning | C16: =IF(A16="","",SUM(LU!O19,LU!O118)) -> 0 | D16: =IF(A16="","",SUM(LU!D19,LU!D118)) -> 0 | E16: =IF(A16="","",SUM(LU!J19,LU!J118)) -> 20 | F16: =IF(A16="","",(SUM(C16:E16)-(SUMPRODUCT(--(Lineups!C$4:C$41=A16),--(Lineups!A$4:A$41="SP"))+SUMPRODUCT(--(Lineups!G$4:G$41=A16),--(Lineups!A$4:A$41="SP"))+SUMPRODUCT(--(Lineups!C$46:C$83=A16),--(Lineups!A$46:A$83="SP"))+SUMPRODUCT(--(Lineups!G$46:G$83=A16),--(Lineups!A$46:A$83="SP"))))) -> 20 | G16: =IF(OR(A16="",F16=0,LU!D$3+LU!D$102=0),"",F16/(LU!D$3+LU!D$102)) -> 0.45454545 | H16: =IF(OR(C16=0,A16=""),"",SK!D204) | I16: =IF(OR(A16="",SK!E204="",SK!E204=0),"",H16/SK!E204) | J16: =IF(OR(A16="",C16=0),"",SK!G204) | K16: =IF(OR(A16="",C16=0),"",SK!H204) | L16: =IF(OR(A16="",C16=0),"",SK!J204) | M16: =IF(OR(A16="",C16=0),"",SK!L204) | N16: =IF(OR(A16="",C16=0),"",SUMPRODUCT(--(Lineups!$A$4:$A$41="SP"),--(Lineups!$C$4:$C$41=A16))+SUMPRODUCT(--(Lineups!$A$46:$A$83="SP"),--(Lineups!$C$46:$C$83=A16))) | O16: =IF(OR(A16="",C16="",(IF(C16="",0,C16)-IF(N16="",0,N16))=0),"",K16/(C16-N16)) | P16: =IF(OR(A16="",C16=0),"",SK!I204) | Q16: =IF(OR(A16="",C16=0,K16=0),"",P16/K16) | R16: =IF(OR(A16="",F16=0),"",SUM(LU!Q65,LU!Q164)) -> 72 | S16: =IF(OR(A16="",F16=0),"",SUM(LU!Q88,LU!Q187)) -> 119 | T16: =IF(OR(A16="",F16=0),"",SUM(LU!Q42,LU!Q141)) -> -47 | U16: =IF(OR(A16="",C16=0),"",SUM(LU!O42,LU!O141)) | V16: =IF(OR(A16="",C16=0),"",U16/C16) | W16: =IF(OR(A16="",D16=0),"",SUM(LU!D42,LU!D141)) | X16: =IF(OR(A16="",D16=0),"",W16/D16) | Y16: =IF(OR(A16="",E16=0),"",SUM(LU!J42,LU!J141)) -> -47 | Z16: =IF(OR(A16="",E16=0),"",Y16/E16) -> -2.35 | AA16: =IF(OR(A16="",AND(D16=0, E16=0)),"",SUM(LU!L42,LU!L141)) -> -47 | AB16: =IF(OR(A16="",AND(D16=0, E16=0)),"",AA16/(D16+E16)) -> -2.35 | AC16: =IF(OR(A16="",F16="",F16=0),"",T16/F16) -> -2.35 | AD16: =IF(OR(A16="",F16=0,R$26="-",LU!$D$5=0),"",R16-R$26) -> 26.333333 | AE16: =IF(OR(A16="",F16=0,S$26="-",LU!$D$5=0),"",S16-S$26) -> 29 | AF16: =IF(OR(A16="",F16=0,AD16=""),"",AD16-AE16) -> -2.6666667 | AG16: =IF(OR($A16="",C16=0),"",V16-V$26) | AH16: =IF(OR($A16="",D16=0),"",X16-X$26) | AI16: =IF(OR($A16="",E16=0),"",Z16-Z$26) -> 0.073870636 | AJ16: =IF(OR($A16="",AND(D16=0, E16=0)),"",AB16-AB$26) -> 0.22333054 | AK16: =IF(OR($A16="",AC16="",AC$26="-",LU!$D$5=0),"",AC16-AC$26) -> 0.56710605 | AL16: =IF(OR(A16="",F16=0),"",SUM(PT!U23,PT!U24)) -> 4
A17: =IF(ISBLANK(IGRF!$B25),"",IGRF!$B25) -> 720 | B17: =IF(ISBLANK(IGRF!$C25),"",IGRF!$C25) -> Bob Gnarly | C17: =IF(A17="","",SUM(LU!O20,LU!O119)) -> 0 | D17: =IF(A17="","",SUM(LU!D20,LU!D119)) -> 0 | E17: =IF(A17="","",SUM(LU!J20,LU!J119)) -> 10 | F17: =IF(A17="","",(SUM(C17:E17)-(SUMPRODUCT(--(Lineups!C$4:C$41=A17),--(Lineups!A$4:A$41="SP"))+SUMPRODUCT(--(Lineups!G$4:G$41=A17),--(Lineups!A$4:A$41="SP"))+SUMPRODUCT(--(Lineups!C$46:C$83=A17),--(Lineups!A$46:A$83="SP"))+SUMPRODUCT(--(Lineups!G$46:G$83=A17),--(Lineups!A$46:A$83="SP"))))) -> 10 | G17: =IF(OR(A17="",F17=0,LU!D$3+LU!D$102=0),"",F17/(LU!D$3+LU!D$102)) -> 0.22727273 | H17: =IF(OR(C17=0,A17=""),"",SK!D207) | I17: =IF(OR(A17="",SK!E207="",SK!E207=0),"",H17/SK!E207) | J17: =IF(OR(A17="",C17=0),"",SK!G207) | K17: =IF(OR(A17="",C17=0),"",SK!H207) | L17: =IF(OR(A17="",C17=0),"",SK!J207) | M17: =IF(OR(A17="",C17=0),"",SK!L207) | N17: =IF(OR(A17="",C17=0),"",SUMPRODUCT(--(Lineups!$A$4:$A$41="SP"),--(Lineups!$C$4:$C$41=A17))+SUMPRODUCT(--(Lineups!$A$46:$A$83="SP"),--(Lineups!$C$46:$C$83=A17))) | O17: =IF(OR(A17="",C17="",(IF(C17="",0,C17)-IF(N17="",0,N17))=0),"",K17/(C17-N17)) | P17: =IF(OR(A17="",C17=0),"",SK!I207) | Q17: =IF(OR(A17="",C17=0,K17=0),"",P17/K17) | R17: =IF(OR(A17="",F17=0),"",SUM(LU!Q66,LU!Q165)) -> 48 | S17: =IF(OR(A17="",F17=0),"",SUM(LU!Q89,LU!Q188)) -> 61 | T17: =IF(OR(A17="",F17=0),"",SUM(LU!Q43,LU!Q142)) -> -13 | U17: =IF(OR(A17="",C17=0),"",SUM(LU!O43,LU!O142)) | V17: =IF(OR(A17="",C17=0),"",U17/C17) | W17: =IF(OR(A17="",D17=0),"",SUM(LU!D43,LU!D142)) | X17: =IF(OR(A17="",D17=0),"",W17/D17) | Y17: =IF(OR(A17="",E17=0),"",SUM(LU!J43,LU!J142)) -> -13 | Z17: =IF(OR(A17="",E17=0),"",Y17/E17) -> -1.3 | AA17: =IF(OR(A17="",AND(D17=0, E17=0)),"",SUM(LU!L43,LU!L142)) -> -13 | AB17: =IF(OR(A17="",AND(D17=0, E17=0)),"",AA17/(D17+E17)) -> -1.3 | AC17: =IF(OR(A17="",F17="",F17=0),"",T17/F17) -> -1.3 | AD17: =IF(OR(A17="",F17=0,R$26="-",LU!$D$5=0),"",R17-R$26) -> 2.3333333 | AE17: =IF(OR(A17="",F17=0,S$26="-",LU!$D$5=0),"",S17-S$26) -> -29 | AF17: =IF(OR(A17="",F17=0,AD17=""),"",AD17-AE17) -> 31.333333 | AG17: =IF(OR($A17="",C17=0),"",V17-V$26) | AH17: =IF(OR($A17="",D17=0),"",X17-X$26) | AI17: =IF(OR($A17="",E17=0),"",Z17-Z$26) -> 1.1238706 | AJ17: =IF(OR($A17="",AND(D17=0, E17=0)),"",AB17-AB$26) -> 1.2733305 | AK17: =IF(OR($A17="",AC17="",AC$26="-",LU!$D$5=0),"",AC17-AC$26) -> 1.617106 | AL17: =IF(OR(A17="",F17=0),"",SUM(PT!U25,PT!U26)) -> 2
A18: =IF(ISBLANK(IGRF!$B26),"",IGRF!$B26) -> 737 | B18: =IF(ISBLANK(IGRF!$C26),"",IGRF!$C26) -> Lady J | C18: =IF(A18="","",SUM(LU!O21,LU!O120)) -> 9 | D18: =IF(A18="","",SUM(LU!D21,LU!D120)) -> 1 | E18: =IF(A18="","",SUM(LU!J21,LU!J120)) -> 1 | F18: =IF(A18="","",(SUM(C18:E18)-(SUMPRODUCT(--(Lineups!C$4:C$41=A18),--(Lineups!A$4:A$41="SP"))+SUMPRODUCT(--(Lineups!G$4:G$41=A18),--(Lineups!A$4:A$41="SP"))+SUMPRODUCT(--(Lineups!C$46:C$83=A18),--(Lineups!A$46:A$83="SP"))+SUMPRODUCT(--(Lineups!G$46:G$83=A18),--(Lineups!A$46:A$83="SP"))))) -> 10 | G18: =IF(OR(A18="",F18=0,LU!D$3+LU!D$102=0),"",F18/(LU!D$3+LU!D$102)) -> 0.22727273 | H18: =IF(OR(C18=0,A18=""),"",SK!D210) -> 43 | I18: =IF(OR(A18="",SK!E210="",SK!E210=0),"",H18/SK!E210) -> 4.7777778 | J18: =IF(OR(A18="",C18=0),"",SK!G210) -> 0 | K18: =IF(OR(A18="",C18=0),"",SK!H210) -> 5 | L18: =IF(OR(A18="",C18=0),"",SK!J210) -> 4 | M18: =IF(OR(A18="",C18=0),"",SK!L210) -> 2 | N18: =IF(OR(A18="",C18=0),"",SUMPRODUCT(--(Lineups!$A$4:$A$41="SP"),--(Lineups!$C$4:$C$41=A18))+SUMPRODUCT(--(Lineups!$A$46:$A$83="SP"),--(Lineups!$C$46:$C$83=A18))) -> 0 | O18: =IF(OR(A18="",C18="",(IF(C18="",0,C18)-IF(N18="",0,N18))=0),"",K18/(C18-N18)) -> 0.55555556 | P18: =IF(OR(A18="",C18=0),"",SK!I210) -> 20 | Q18: =IF(OR(A18="",C18=0,K18=0),"",P18/K18) -> 4 | R18: =IF(OR(A18="",F18=0),"",SUM(LU!Q67,LU!Q166)) -> 47 | S18: =IF(OR(A18="",F18=0),"",SUM(LU!Q90,LU!Q189)) -> 60 | T18: =IF(OR(A18="",F18=0),"",SUM(LU!Q44,LU!Q143)) -> -13 | U18: =IF(OR(A18="",C18=0),"",SUM(LU!O44,LU!O143)) -> -9 | V18: =IF(OR(A18="",C18=0),"",U18/C18) -> -1 | W18: =IF(OR(A18="",D18=0),"",SUM(LU!D44,LU!D143)) -> -4 | X18: =IF(OR(A18="",D18=0),"",W18/D18) -> -4 | Y18: =IF(OR(A18="",E18=0),"",SUM(LU!J44,LU!J143)) -> 0 | Z18: =IF(OR(A18="",E18=0),"",Y18/E18) -> 0 | AA18: =IF(OR(A18="",AND(D18=0, E18=0)),"",SUM(LU!L44,LU!L143)) -> -4 | AB18: =IF(OR(A18="",AND(D18=0, E18=0)),"",AA18/(D18+E18)) -> -2 | AC18: =IF(OR(A18="",F18="",F18=0),"",T18/F18) -> -1.3 | AD18: =IF(OR(A18="",F18=0,R$26="-",LU!$D$5=0),"",R18-R$26) -> 1.3333333 | AE18: =IF(OR(A18="",F18=0,S$26="-",LU!$D$5=0),"",S18-S$26) -> -30 | AF18: =IF(OR(A18="",F18=0,AD18=""),"",AD18-AE18) -> 31.333333 | AG18: =IF(OR($A18="",C18=0),"",V18-V$26) -> 1.971584 | AH18: =IF(OR($A18="",D18=0),"",X18-X$26) -> -3.4825397 | AI18: =IF(OR($A18="",E18=0),"",Z18-Z$26) -> 2.4238706 | AJ18: =IF(OR($A18="",AND(D18=0, E18=0)),"",AB18-AB$26) -> 0.57333054 | AK18: =IF(OR($A18="",AC18="",AC$26="-",LU!$D$5=0),"",AC18-AC$26) -> 1.617106 | AL18: =IF(OR(A18="",F18=0),"",SUM(PT!U27,PT!U28)) -> 0
A19: =IF(ISBLANK(IGRF!$B27),"",IGRF!$B27) -> 802 | B19: =IF(ISBLANK(IGRF!$C27),"",IGRF!$C27) -> Rutabaga Ginsberg (Baga) | C19: =IF(A19="","",SUM(LU!O22,LU!O121)) -> 0 | D19: =IF(A19="","",SUM(LU!D22,LU!D121)) -> 2 | E19: =IF(A19="","",SUM(LU!J22,LU!J121)) -> 16 | F19: =IF(A19="","",(SUM(C19:E19)-(SUMPRODUCT(--(Lineups!C$4:C$41=A19),--(Lineups!A$4:A$41="SP"))+SUMPRODUCT(--(Lineups!G$4:G$41=A19),--(Lineups!A$4:A$41="SP"))+SUMPRODUCT(--(Lineups!C$46:C$83=A19),--(Lineups!A$46:A$83="SP"))+SUMPRODUCT(--(Lineups!G$46:G$83=A19),--(Lineups!A$46:A$83="SP"))))) -> 18 | G19: =IF(OR(A19="",F19=0,LU!D$3+LU!D$102=0),"",F19/(LU!D$3+LU!D$102)) -> 0.40909091 | H19: =IF(OR(C19=0,A19=""),"",SK!D213) | I19: =IF(OR(A19="",SK!E213="",SK!E213=0),"",H19/SK!E213) | J19: =IF(OR(A19="",C19=0),"",SK!G213) | K19: =IF(OR(A19="",C19=0),"",SK!H213) | L19: =IF(OR(A19="",C19=0),"",SK!J213) | M19: =IF(OR(A19="",C19=0),"",SK!L213) | N19: =IF(OR(A19="",C19=0),"",SUMPRODUCT(--(Lineups!$A$4:$A$41="SP"),--(Lineups!$C$4:$C$41=A19))+SUMPRODUCT(--(Lineups!$A$46:$A$83="SP"),--(Lineups!$C$46:$C$83=A19))) | O19: =IF(OR(A19="",C19="",(IF(C19="",0,C19)-IF(N19="",0,N19))=0),"",K19/(C19-N19)) | P19: =IF(OR(A19="",C19=0),"",SK!I213) | Q19: =IF(OR(A19="",C19=0,K19=0),"",P19/K19) | R19: =IF(OR(A19="",F19=0),"",SUM(LU!Q68,LU!Q167)) -> 61 | S19: =IF(OR(A19="",F19=0),"",SUM(LU!Q91,LU!Q190)) -> 72 | T19: =IF(OR(A19="",F19=0),"",SUM(LU!Q45,LU!Q144)) -> -11 | U19: =IF(OR(A19="",C19=0),"",SUM(LU!O45,LU!O144)) | V19: =IF(OR(A19="",C19=0),"",U19/C19) | W19: =IF(OR(A19="",D19=0),"",SUM(LU!D45,LU!D144)) -> 0 | X19: =IF(OR(A19="",D19=0),"",W19/D19) -> 0 | Y19: =IF(OR(A19="",E19=0),"",SUM(LU!J45,LU!J144)) -> -11 | Z19: =IF(OR(A19="",E19=0),"",Y19/E19) -> -0.6875 | AA19: =IF(OR(A19="",AND(D19=0, E19=0)),"",SUM(LU!L45,LU!L144)) -> -11 | AB19: =IF(OR(A19="",AND(D19=0, E19=0)),"",AA19/(D19+E19)) -> -0.61111111 | AC19: =IF(OR(A19="",F19="",F19=0),"",T19/F19) -> -0.61111111 | AD19: =IF(OR(A19="",F19=0,R$26="-",LU!$D$5=0),"",R19-R$26) -> 15.333333 | AE19: =IF(OR(A19="",F19=0,S$26="-",LU!$D$5=0),"",S19-S$26) -> -18 | AF19: =IF(OR(A19="",F19=0,AD19=""),"",AD19-AE19) -> 33.333333 | AG19: =IF(OR($A19="",C19=0),"",V19-V$26) | AH19: =IF(OR($A19="",D19=0),"",X19-X$26) -> 0.51746032 | AI19: =IF(OR($A19="",E19=0),"",Z19-Z$26) -> 1.7363706 | AJ19: =IF(OR($A19="",AND(D19=0, E19=0)),"",AB19-AB$26) -> 1.9622194 | AK19: =IF(OR($A19="",AC19="",AC$26="-",LU!$D$5=0),"",AC19-AC$26) -> 2.3059949 | AL19: =IF(OR(A19="",F19=0),"",SUM(PT!U29,PT!U30)) -> 2
A20: =IF(ISBLANK(IGRF!$B28),"",IGRF!$B28) -> 86 | B20: =IF(ISBLANK(IGRF!$C28),"",IGRF!$C28) -> Glidezilla | C20: =IF(A20="","",SUM(LU!O23,LU!O122)) -> 1 | D20: =IF(A20="","",SUM(LU!D23,LU!D122)) -> 0 | E20: =IF(A20="","",SUM(LU!J23,LU!J122)) -> 6 | F20: =IF(A20="","",(SUM(C20:E20)-(SUMPRODUCT(--(Lineups!C$4:C$41=A20),--(Lineups!A$4:A$41="SP"))+SUMPRODUCT(--(Lineups!G$4:G$41=A20),--(Lineups!A$4:A$41="SP"))+SUMPRODUCT(--(Lineups!C$46:C$83=A20),--(Lineups!A$46:A$83="SP"))+SUMPRODUCT(--(Lineups!G$46:G$83=A20),--(Lineups!A$46:A$83="SP"))))) -> 6 | G20: =IF(OR(A20="",F20=0,LU!D$3+LU!D$102=0),"",F20/(LU!D$3+LU!D$102)) -> 0.13636364 | H20: =IF(OR(C20=0,A20=""),"",SK!D216) -> 0 | I20: =IF(OR(A20="",SK!E216="",SK!E216=0),"",H20/SK!E216) -> 0 | J20: =IF(OR(A20="",C20=0),"",SK!G216) -> 0 | K20: =IF(OR(A20="",C20=0),"",SK!H216) -> 0 | L20: =IF(OR(A20="",C20=0),"",SK!J216) -> 0 | M20: =IF(OR(A20="",C20=0),"",SK!L216) -> 1 | N20: =IF(OR(A20="",C20=0),"",SUMPRODUCT(--(Lineups!$A$4:$A$41="SP"),--(Lineups!$C$4:$C$41=A20))+SUMPRODUCT(--(Lineups!$A$46:$A$83="SP"),--(Lineups!$C$46:$C$83=A20))) -> 0 | O20: =IF(OR(A20="",C20="",(IF(C20="",0,C20)-IF(N20="",0,N20))=0),"",K20/(C20-N20)) -> 0 | P20: =IF(OR(A20="",C20=0),"",SK!I216) -> 0 | Q20: =IF(OR(A20="",C20=0,K20=0),"",P20/K20) | R20: =IF(OR(A20="",F20=0),"",SUM(LU!Q69,LU!Q168)) -> 19 | S20: =IF(OR(A20="",F20=0),"",SUM(LU!Q92,LU!Q191)) -> 38 | T20: =IF(OR(A20="",F20=0),"",SUM(LU!Q46,LU!Q145)) -> -19 | U20: =IF(OR(A20="",C20=0),"",SUM(LU!O46,LU!O145)) -> -8 | V20: =IF(OR(A20="",C20=0),"",U20/C20) -> -8 | W20: =IF(OR(A20="",D20=0),"",SUM(LU!D46,LU!D145)) | X20: =IF(OR(A20="",D20=0),"",W20/D20) | Y20: =IF(OR(A20="",E20=0),"",SUM(LU!J46,LU!J145)) -> -11 | Z20: =IF(OR(A20="",E20=0),"",Y20/E20) -> -1.8333333 | AA20: =IF(OR(A20="",AND(D20=0, E20=0)),"",SUM(LU!L46,LU!L145)) -> -11 | AB20: =IF(OR(A20="",AND(D20=0, E20=0)),"",AA20/(D20+E20)) -> -1.8333333 | AC20: =IF(OR(A20="",F20="",F20=0),"",T20/F20) -> -3.1666667 | AD20: =IF(OR(A20="",F20=0,R$26="-",LU!$D$5=0),"",R20-R$26) -> -26.666667 | AE20: =IF(OR(A20="",F20=0,S$26="-",LU!$D$5=0),"",S20-S$26) -> -52 | AF20: =IF(OR(A20="",F20=0,AD20=""),"",AD20-AE20) -> 25.333333 | AG20: =IF(OR($A20="",C20=0),"",V20-V$26) -> -5.028416 | AH20: =IF(OR($A20="",D20=0),"",X20-X$26) | AI20: =IF(OR($A20="",E20=0),"",Z20-Z$26) -> 0.5905373 | AJ20: =IF(OR($A20="",AND(D20=0, E20=0)),"",AB20-AB$26) -> 0.73999721 | AK20: =IF(OR($A20="",AC20="",AC$26="-",LU!$D$5=0),"",AC20-AC$26) -> -0.24956062 | AL20: =IF(OR(A20="",F20=0),"",SUM(PT!U31,PT!U32)) -> 1
A21: =IF(ISBLANK(IGRF!$B29),"",IGRF!$B29) -> 98 | B21: =IF(ISBLANK(IGRF!$C29),"",IGRF!$C29) -> Badelynn | C21: =IF(A21="","",SUM(LU!O24,LU!O123)) -> 11 | D21: =IF(A21="","",SUM(LU!D24,LU!D123)) -> 0 | E21: =IF(A21="","",SUM(LU!J24,LU!J123)) -> 0 | F21: =IF(A21="","",(SUM(C21:E21)-(SUMPRODUCT(--(Lineups!C$4:C$41=A21),--(Lineups!A$4:A$41="SP"))+SUMPRODUCT(--(Lineups!G$4:G$41=A21),--(Lineups!A$4:A$41="SP"))+SUMPRODUCT(--(Lineups!C$46:C$83=A21),--(Lineups!A$46:A$83="SP"))+SUMPRODUCT(--(Lineups!G$46:G$83=A21),--(Lineups!A$46:A$83="SP"))))) -> 11 | G21: =IF(OR(A21="",F21=0,LU!D$3+LU!D$102=0),"",F21/(LU!D$3+LU!D$102)) -> 0.25 | H21: =IF(OR(C21=0,A21=""),"",SK!D219) -> 46 | I21: =IF(OR(A21="",SK!E219="",SK!E219=0),"",H21/SK!E219) -> 4.1818182 | J21: =IF(OR(A21="",C21=0),"",SK!G219) -> 0 | K21: =IF(OR(A21="",C21=0),"",SK!H219) -> 3 | L21: =IF(OR(A21="",C21=0),"",SK!J219) -> 3 | M21: =IF(OR(A21="",C21=0),"",SK!L219) -> 1 | N21: =IF(OR(A21="",C21=0),"",SUMPRODUCT(--(Lineups!$A$4:$A$41="SP"),--(Lineups!$C$4:$C$41=A21))+SUMPRODUCT(--(Lineups!$A$46:$A$83="SP"),--(Lineups!$C$46:$C$83=A21))) -> 0 | O21: =IF(OR(A21="",C21="",(IF(C21="",0,C21)-IF(N21="",0,N21))=0),"",K21/(C21-N21)) -> 0.27272727 | P21: =IF(OR(A21="",C21=0),"",SK!I219) -> 9 | Q21: =IF(OR(A21="",C21=0,K21=0),"",P21/K21) -> 3 | R21: =IF(OR(A21="",F21=0),"",SUM(LU!Q70,LU!Q169)) -> 46 | S21: =IF(OR(A21="",F21=0),"",SUM(LU!Q93,LU!Q192)) -> 77 | T21: =IF(OR(A21="",F21=0),"",SUM(LU!Q47,LU!Q146)) -> -31 | U21: =IF(OR(A21="",C21=0),"",SUM(LU!O47,LU!O146)) -> -31 | V21: =IF(OR(A21="",C21=0),"",U21/C21) -> -2.8181818 | W21: =IF(OR(A21="",D21=0),"",SUM(LU!D47,LU!D146)) | X21: =IF(OR(A21="",D21=0),"",W21/D21) | Y21: =IF(OR(A21="",E21=0),"",SUM(LU!J47,LU!J146)) | Z21: =IF(OR(A21="",E21=0),"",Y21/E21) | AA21: =IF(OR(A21="",AND(D21=0, E21=0)),"",SUM(LU!L47,LU!L146)) | AB21: =IF(OR(A21="",AND(D21=0, E21=0)),"",AA21/(D21+E21)) | AC21: =IF(OR(A21="",F21="",F21=0),"",T21/F21) -> -2.8181818 | AD21: =IF(OR(A21="",F21=0,R$26="-",LU!$D$5=0),"",R21-R$26) -> 0.33333333 | AE21: =IF(OR(A21="",F21=0,S$26="-",LU!$D$5=0),"",S21-S$26) -> -13 | AF21: =IF(OR(A21="",F21=0,AD21=""),"",AD21-AE21) -> 13.333333 | AG21: =IF(OR($A21="",C21=0),"",V21-V$26) -> 0.15340215 | AH21: =IF(OR($A21="",D21=0),"",X21-X$26) | AI21: =IF(OR($A21="",E21=0),"",Z21-Z$26) | AJ21: =IF(OR($A21="",AND(D21=0, E21=0)),"",AB21-AB$26) | AK21: =IF(OR($A21="",AC21="",AC$26="-",LU!$D$5=0),"",AC21-AC$26) -> 0.09892423 | AL21: =IF(OR(A21="",F21=0),"",SUM(PT!U33,PT!U34)) -> 2
A22: =IF(ISBLANK(IGRF!$B30),"",IGRF!$B30) | B22: =IF(ISBLANK(IGRF!$C30),"",IGRF!$C30) | C22: =IF(A22="","",SUM(LU!O25,LU!O124)) | D22: =IF(A22="","",SUM(LU!D25,LU!D124)) | E22: =IF(A22="","",SUM(LU!J25,LU!J124)) | F22: =IF(A22="","",(SUM(C22:E22)-(SUMPRODUCT(--(Lineups!C$4:C$41=A22),--(Lineups!A$4:A$41="SP"))+SUMPRODUCT(--(Lineups!G$4:G$41=A22),--(Lineups!A$4:A$41="SP"))+SUMPRODUCT(--(Lineups!C$46:C$83=A22),--(Lineups!A$46:A$83="SP"))+SUMPRODUCT(--(Lineups!G$46:G$83=A22),--(Lineups!A$46:A$83="SP"))))) | G22: =IF(OR(A22="",F22=0,LU!D$3+LU!D$102=0),"",F22/(LU!D$3+LU!D$102)) | H22: =IF(OR(C22=0,A22=""),"",SK!D222) | I22: =IF(OR(A22="",SK!E222="",SK!E222=0),"",H22/SK!E222) | J22: =IF(OR(A22="",C22=0),"",SK!G222) | K22: =IF(OR(A22="",C22=0),"",SK!H222) | L22: =IF(OR(A22="",C22=0),"",SK!J222) | M22: =IF(OR(A22="",C22=0),"",SK!L222) | N22: =IF(OR(A22="",C22=0),"",SUMPRODUCT(--(Lineups!$A$4:$A$41="SP"),--(Lineups!$C$4:$C$41=A22))+SUMPRODUCT(--(Lineups!$A$46:$A$83="SP"),--(Lineups!$C$46:$C$83=A22))) | O22: =IF(OR(A22="",C22="",(IF(C22="",0,C22)-IF(N22="",0,N22))=0),"",K22/(C22-N22)) | P22: =IF(OR(A22="",C22=0),"",SK!I222) | Q22: =IF(OR(A22="",C22=0,K22=0),"",P22/K22) | R22: =IF(OR(A22="",F22=0),"",SUM(LU!Q71,LU!Q170)) | S22: =IF(OR(A22="",F22=0),"",SUM(LU!Q94,LU!Q193)) | T22: =IF(OR(A22="",F22=0),"",SUM(LU!Q48,LU!Q147)) | U22: =IF(OR(A22="",C22=0),"",SUM(LU!O48,LU!O147)) | V22: =IF(OR(A22="",C22=0),"",U22/C22) | W22: =IF(OR(A22="",D22=0),"",SUM(LU!D48,LU!D147)) | X22: =IF(OR(A22="",D22=0),"",W22/D22) | Y22: =IF(OR(A22="",E22=0),"",SUM(LU!J48,LU!J147)) | Z22: =IF(OR(A22="",E22=0),"",Y22/E22) | AA22: =IF(OR(A22="",AND(D22=0, E22=0)),"",SUM(LU!L48,LU!L147)) | AB22: =IF(OR(A22="",AND(D22=0, E22=0)),"",AA22/(D22+E22)) | AC22: =IF(OR(A22="",F22="",F22=0),"",T22/F22) | AD22: =IF(OR(A22="",F22=0,R$26="-",LU!$D$5=0),"",R22-R$26) | AE22: =IF(OR(A22="",F22=0,S$26="-",LU!$D$5=0),"",S22-S$26) | AF22: =IF(OR(A22="",F22=0,AD22=""),"",AD22-AE22) | AG22: =IF(OR($A22="",C22=0),"",V22-V$26) | AH22: =IF(OR($A22="",D22=0),"",X22-X$26) | AI22: =IF(OR($A22="",E22=0),"",Z22-Z$26) | AJ22: =IF(OR($A22="",AND(D22=0, E22=0)),"",AB22-AB$26) | AK22: =IF(OR($A22="",AC22="",AC$26="-",LU!$D$5=0),"",AC22-AC$26) | AL22: =IF(OR(A22="",F22=0),"",SUM(PT!U35,PT!U36))
A23: =IF(ISBLANK(IGRF!$B31),"",IGRF!$B31) | B23: =IF(ISBLANK(IGRF!$C31),"",IGRF!$C31) | C23: =IF(A23="","",SUM(LU!O26,LU!O125)) | D23: =IF(A23="","",SUM(LU!D26,LU!D125)) | E23: =IF(A23="","",SUM(LU!J26,LU!J125)) | F23: =IF(A23="","",(SUM(C23:E23)-(SUMPRODUCT(--(Lineups!C$4:C$41=A23),--(Lineups!A$4:A$41="SP"))+SUMPRODUCT(--(Lineups!G$4:G$41=A23),--(Lineups!A$4:A$41="SP"))+SUMPRODUCT(--(Lineups!C$46:C$83=A23),--(Lineups!A$46:A$83="SP"))+SUMPRODUCT(--(Lineups!G$46:G$83=A23),--(Lineups!A$46:A$83="SP"))))) | G23: =IF(OR(A23="",F23=0,LU!D$3+LU!D$102=0),"",F23/(LU!D$3+LU!D$102)) | H23: =IF(OR(C23=0,A23=""),"",SK!D225) | I23: =IF(OR(A23="",SK!E225="",SK!E225=0),"",H23/SK!E225) | J23: =IF(OR(A23="",C23=0),"",SK!G225) | K23: =IF(OR(A23="",C23=0),"",SK!H225) | L23: =IF(OR(A23="",C23=0),"",SK!J225) | M23: =IF(OR(A23="",C23=0),"",SK!L225) | N23: =IF(OR(A23="",C23=0),"",SUMPRODUCT(--(Lineups!$A$4:$A$41="SP"),--(Lineups!$C$4:$C$41=A23))+SUMPRODUCT(--(Lineups!$A$46:$A$83="SP"),--(Lineups!$C$46:$C$83=A23))) | O23: =IF(OR(A23="",C23="",(IF(C23="",0,C23)-IF(N23="",0,N23))=0),"",K23/(C23-N23)) | P23: =IF(OR(A23="",C23=0),"",SK!I225) | Q23: =IF(OR(A23="",C23=0,K23=0),"",P23/K23) | R23: =IF(OR(A23="",F23=0),"",SUM(LU!Q72,LU!Q171)) | S23: =IF(OR(A23="",F23=0),"",SUM(LU!Q95,LU!Q194)) | T23: =IF(OR(A23="",F23=0),"",SUM(LU!Q49,LU!Q148)) | U23: =IF(OR(A23="",C23=0),"",SUM(LU!O49,LU!O148)) | V23: =IF(OR(A23="",C23=0),"",U23/C23) | W23: =IF(OR(A23="",D23=0),"",SUM(LU!D49,LU!D148)) | X23: =IF(OR(A23="",D23=0),"",W23/D23) | Y23: =IF(OR(A23="",E23=0),"",SUM(LU!J49,LU!J148)) | Z23: =IF(OR(A23="",E23=0),"",Y23/E23) | AA23: =IF(OR(A23="",AND(D23=0, E23=0)),"",SUM(LU!L49,LU!L148)) | AB23: =IF(OR(A23="",AND(D23=0, E23=0)),"",AA23/(D23+E23)) | AC23: =IF(OR(A23="",F23="",F23=0),"",T23/F23) | AD23: =IF(OR(A23="",F23=0,R$26="-",LU!$D$5=0),"",R23-R$26) | AE23: =IF(OR(A23="",F23=0,S$26="-",LU!$D$5=0),"",S23-S$26) | AF23: =IF(OR(A23="",F23=0,AD23=""),"",AD23-AE23) | AG23: =IF(OR($A23="",C23=0),"",V23-V$26) | AH23: =IF(OR($A23="",D23=0),"",X23-X$26) | AI23: =IF(OR($A23="",E23=0),"",Z23-Z$26) | AJ23: =IF(OR($A23="",AND(D23=0, E23=0)),"",AB23-AB$26) | AK23: =IF(OR($A23="",AC23="",AC$26="-",LU!$D$5=0),"",AC23-AC$26) | AL23: =IF(OR(A23="",F23=0),"",SUM(PT!U37,PT!U38))
A24: =IF(ISBLANK(IGRF!$B32),"",IGRF!$B32) | B24: =IF(ISBLANK(IGRF!$C32),"",IGRF!$C32) | C24: =IF(A24="","",SUM(LU!O27,LU!O126)) | D24: =IF(A24="","",SUM(LU!D27,LU!D126)) | E24: =IF(A24="","",SUM(LU!J27,LU!J126)) | F24: =IF(A24="","",(SUM(C24:E24)-(SUMPRODUCT(--(Lineups!C$4:C$41=A24),--(Lineups!A$4:A$41="SP"))+SUMPRODUCT(--(Lineups!G$4:G$41=A24),--(Lineups!A$4:A$41="SP"))+SUMPRODUCT(--(Lineups!C$46:C$83=A24),--(Lineups!A$46:A$83="SP"))+SUMPRODUCT(--(Lineups!G$46:G$83=A24),--(Lineups!A$46:A$83="SP"))))) | G24: =IF(OR(A24="",F24=0,LU!D$3+LU!D$102=0),"",F24/(LU!D$3+LU!D$102)) | H24: =IF(OR(C24=0,A24=""),"",SK!D228) | I24: =IF(OR(A24="",SK!E228="",SK!E228=0),"",H24/SK!E228) | J24: =IF(OR(A24="",C24=0),"",SK!G228) | K24: =IF(OR(A24="",C24=0),"",SK!H228) | L24: =IF(OR(A24="",C24=0),"",SK!J228) | M24: =IF(OR(A24="",C24=0),"",SK!L228) | N24: =IF(OR(A24="",C24=0),"",SUMPRODUCT(--(Lineups!$A$4:$A$41="SP"),--(Lineups!$C$4:$C$41=A24))+SUMPRODUCT(--(Lineups!$A$46:$A$83="SP"),--(Lineups!$C$46:$C$83=A24))) | O24: =IF(OR(A24="",C24="",(IF(C24="",0,C24)-IF(N24="",0,N24))=0),"",K24/(C24-N24)) | P24: =IF(OR(A24="",C24=0),"",SK!I228) | Q24: =IF(OR(A24="",C24=0,K24=0),"",P24/K24) | R24: =IF(OR(A24="",F24=0),"",SUM(LU!Q73,LU!Q172)) | S24: =IF(OR(A24="",F24=0),"",SUM(LU!Q96,LU!Q195)) | T24: =IF(OR(A24="",F24=0),"",SUM(LU!Q50,LU!Q149)) | U24: =IF(OR(A24="",C24=0),"",SUM(LU!O50,LU!O149)) | V24: =IF(OR(A24="",C24=0),"",U24/C24) | W24: =IF(OR(A24="",D24=0),"",SUM(LU!D50,LU!D149)) | X24: =IF(OR(A24="",D24=0),"",W24/D24) | Y24: =IF(OR(A24="",E24=0),"",SUM(LU!J50,LU!J149)) | Z24: =IF(OR(A24="",E24=0),"",Y24/E24) | AA24: =IF(OR(A24="",AND(D24=0, E24=0)),"",SUM(LU!L50,LU!L149)) | AB24: =IF(OR(A24="",AND(D24=0, E24=0)),"",AA24/(D24+E24)) | AC24: =IF(OR(A24="",F24="",F24=0),"",T24/F24) | AD24: =IF(OR(A24="",F24=0,R$26="-",LU!$D$5=0),"",R24-R$26) | AE24: =IF(OR(A24="",F24=0,S$26="-",LU!$D$5=0),"",S24-S$26) | AF24: =IF(OR(A24="",F24=0,AD24=""),"",AD24-AE24) | AG24: =IF(OR($A24="",C24=0),"",V24-V$26) | AH24: =IF(OR($A24="",D24=0),"",X24-X$26) | AI24: =IF(OR($A24="",E24=0),"",Z24-Z$26) | AJ24: =IF(OR($A24="",AND(D24=0, E24=0)),"",AB24-AB$26) | AK24: =IF(OR($A24="",AC24="",AC$26="-",LU!$D$5=0),"",AC24-AC$26) | AL24: =IF(OR(A24="",F24=0),"",SUM(PT!U39,PT!U40))
A25: =IF(ISBLANK(IGRF!$B33),"",IGRF!$B33) | B25: =IF(ISBLANK(IGRF!$C33),"",IGRF!$C33) | C25: =IF(A25="","",SUM(LU!O28,LU!O127)) | D25: =IF(A25="","",SUM(LU!D28,LU!D127)) | E25: =IF(A25="","",SUM(LU!J28,LU!J127)) | F25: =IF(A25="","",(SUM(C25:E25)-(SUMPRODUCT(--(Lineups!C$4:C$41=A25),--(Lineups!A$4:A$41="SP"))+SUMPRODUCT(--(Lineups!G$4:G$41=A25),--(Lineups!A$4:A$41="SP"))+SUMPRODUCT(--(Lineups!C$46:C$83=A25),--(Lineups!A$46:A$83="SP"))+SUMPRODUCT(--(Lineups!G$46:G$83=A25),--(Lineups!A$46:A$83="SP"))))) | G25: =IF(OR(A25="",F25=0,LU!D$3+LU!D$102=0),"",F25/(LU!D$3+LU!D$102)) | H25: =IF(OR(C25=0,A25=""),"",SK!D231) | I25: =IF(OR(A25="",SK!E231="",SK!E231=0),"",H25/SK!E231) | J25: =IF(OR(A25="",C25=0),"",SK!G231) | K25: =IF(OR(A25="",C25=0),"",SK!H231) | L25: =IF(OR(A25="",C25=0),"",SK!J231) | M25: =IF(OR(A25="",C25=0),"",SK!L231) | N25: =IF(OR(A25="",C25=0),"",SUMPRODUCT(--(Lineups!$A$4:$A$41="SP"),--(Lineups!$C$4:$C$41=A25))+SUMPRODUCT(--(Lineups!$A$46:$A$83="SP"),--(Lineups!$C$46:$C$83=A25))) | O25: =IF(OR(A25="",C25="",(IF(C25="",0,C25)-IF(N25="",0,N25))=0),"",K25/(C25-N25)) | P25: =IF(OR(A25="",C25=0),"",SK!I231) | Q25: =IF(OR(A25="",C25=0,K25=0),"",P25/K25) | R25: =IF(OR(A25="",F25=0),"",SUM(LU!Q74,LU!Q173)) | S25: =IF(OR(A25="",F25=0),"",SUM(LU!Q97,LU!Q196)) | T25: =IF(OR(A25="",F25=0),"",SUM(LU!Q51,LU!Q150)) | U25: =IF(OR(A25="",C25=0),"",SUM(LU!O51,LU!O150)) | V25: =IF(OR(A25="",C25=0),"",U25/C25) | W25: =IF(OR(A25="",D25=0),"",SUM(LU!D51,LU!D150)) | X25: =IF(OR(A25="",D25=0),"",W25/D25) | Y25: =IF(OR(A25="",E25=0),"",SUM(LU!J51,LU!J150)) | Z25: =IF(OR(A25="",E25=0),"",Y25/E25) | AA25: =IF(OR(A25="",AND(D25=0, E25=0)),"",SUM(LU!L51,LU!L150)) | AB25: =IF(OR(A25="",AND(D25=0, E25=0)),"",AA25/(D25+E25)) | AC25: =IF(OR(A25="",F25="",F25=0),"",T25/F25) | AD25: =IF(OR(A25="",F25=0,R$26="-",LU!$D$5=0),"",R25-R$26) | AE25: =IF(OR(A25="",F25=0,S$26="-",LU!$D$5=0),"",S25-S$26) | AF25: =IF(OR(A25="",F25=0,AD25=""),"",AD25-AE25) | AG25: =IF(OR($A25="",C25=0),"",V25-V$26) | AH25: =IF(OR($A25="",D25=0),"",X25-X$26) | AI25: =IF(OR($A25="",E25=0),"",Z25-Z$26) | AJ25: =IF(OR($A25="",AND(D25=0, E25=0)),"",AB25-AB$26) | AK25: =IF(OR($A25="",AC25="",AC$26="-",LU!$D$5=0),"",AC25-AC$26) | AL25: =IF(OR(A25="",F25=0),"",SUM(PT!U41,PT!U42))
A26: TEAM SUMMARIES | C26: =SUM(C6:C25) -> 47 | D26: =SUM(D6:D25) -> 44 | E26: =SUM(E6:E25) -> 135 | F26: =SUM(F6:F25) -> 220 | G26: =IF(COUNT(G6:G25)=0,"-",AVERAGE(G6:G25)) -> 0.33333333 | H26: =SUM(H6:H25) -> 137 | I26: =IF(LU!D3+LU!D102=0,"-",H26/(LU!D3+LU!D102)) -> 3.1136364 | J26: =SUM(J6:J25) -> 1 | K26: =SUM(K6:K25) -> 15 | L26: =SUM(L6:L25) -> 12 | M26: =SUM(M6:M25) -> 9 | N26: =SUM(N6:N25) -> 3 | O26: =IF(C26=0,"-",K26/(C26-N26)) -> 0.34090909 | P26: =SUM(P6:P25) -> 36 | Q26: =IF(COUNT(Q6:Q25)=0,"-",AVERAGE(Q6:Q25)) -> 2.3125 | R26: =IF(COUNT(R6:R25)=0,"-",AVERAGE(R6:R25)) -> 45.666667 | S26: =IF(COUNT(S6:S25)=0,"-",AVERAGE(S6:S25)) -> 90 | T26: =IF(COUNT(T6:T25)=0,"-",AVERAGE(T6:T25)) -> -44.333333 | U26: =IF(COUNT(U6:U25)=0,"-",AVERAGE(U6:U25)) -> -19 | V26: =IF(COUNT(V6:V25)=0,"-",AVERAGE(V6:V25)) -> -2.971584 | W26: =IF(COUNT(W6:W25)=0,"-",AVERAGE(W6:W25)) -> -19 | X26: =IF(COUNT(X6:X25)=0,"-",AVERAGE(X6:X25)) -> -0.51746032 | ... AC26: =IF(COUNT(AC6:AC25)=0,"-",AVERAGE(AC6:AC25)) -> -2.917106 | AD26: N/A | AE26: N/A | AF26: N/A | AG26: N/A | AH26: N/A | AI26: N/A | AJ26: N/A | AK26: N/A | AL26: =SUM(AL6:AM25) -> 29
A27: # | B27: =Score!$T$1 -> ROCKY MOUNTAIN ROLLER DERBY / 5280 FIGHT CLUB | C27: JAMMER | D27: PIVOT | E27: BLOCKER | F27: TOTAL | G27: % JAMS SKATED | H27: POINTS | I27: PPJ | J27: LOST | K27: LEAD | L27: CALLED | M27: NO INITIAL TRIP | N27: STAR PASSES RECEIVED | O27: LEAD % | P27: LEAD +/- | Q27: AVERAGE LEAD +/- | R27: PTS FOR | S27: PTS AGAINST | T27: TOTAL +/- | U27: JAMMER +/- | V27: AVERAGE JAMMER +/- | W27: PIVOT +/- | X27: AVERAGE PIVOT +/- | Y27: BLOCK +/- | Z27: AVERAGE BLOCKER +/- | AA27: PACK +/- | AB27: AVERAGE PACK +/- | AC27: AVG +/- | AD27: VTAR PTS FOR | AE27: VTAR PTS AGAINST | AF27: VTAR TOTAL +/- | AG27: VTAR JAMMER AVG +/- | AH27: VTAR PIVOT AVG +/- | AI27: VTAR BLOCKER AVG +/- | AJ27: VTAR PACK AVG +/- | AK27: TOTAL VTAR AVG +/- | AL27: SKATERS PENALTY COUNT
